Workbook

Sheet HeadCount&Database 
A1: ID | B1: Name | C1: Phone Number | D1: Hire Date | E1: Position | F1: Shift | J1: Total Headcount | M1: =SUM(O49:O55,O58:O62,K58:K60,K49:K55) -> 386
A2: 1019 | B2: Mohamed Ibrahim Mohamed Abo Omar | C2: 1013333299 | D2: 45452 | E2: Execution Manager | F2: DW
A3: Shift Manager | H3: Detailed Head count
A4: ID | B4: Name | C4: Phone Number | D4: Hire Date | E4: Position | F4: Shift
A5: 1022 | B5: Nader Helmy Abd elal Abbas | C5: 1099914441 | D5: 45505 | E5: Shift Manager | F5: D
A6: 1023 | B6: Amr Soliman Mahmoud Soliman Rashwan | C6: 1226950094 | D6: 45515 | E6: Shift Manager | F6: B | I6: A Shift | M6: B Shift
A7: 1052 | B7: Hatem Hosny Nafea Ali Moslem | C7: 1066681479 | D7: 45642 | E7: Shift Manager | F7: DW | I7: OPS count | K7: =SUM(K8:K24) -> 93 | M7: OPS count | O7: =SUM(O8:O24) -> 92
A8: 1028 | B8: Shady Gamal Abdel Nasser Mohamed AlQashash | C8: 1033010314 | D8: 45566 | E8: Shift Manager | F8: C | I8: Shift Manager | K8: =COUNTIFS(F2:F458,"A",E2:E458,"Shift Manager") -> 0 | M8: Shift Manager | O8: =COUNTIFS(F2:F458,"B",E2:E458,"Shift Manager") -> 1
A9: Monitoring Team Leader | I9: Operation Supervisor | K9: =COUNTIFS(F2:F458,"A",E2:E458,"Operation Supervisor") -> 2 | M9: Operation Supervisor | O9: =COUNTIFS(F2:F458,"B",E2:E458,"Operation Supervisor") -> 2
A10: ID | B10: Name | C10: Phone Number | D10: Hire Date | E10: Position | F10: Shift | I10: Monitoring Team Leader | K10: =COUNTIFS(F2:F458,"A",E2:E458,"Monitoring Team Leader") -> 1 | M10: Monitoring Team Leader | O10: =COUNTIFS(F2:F458,"B",E2:E458,"Monitoring Team Leader") -> 1 | T10: VLOOKUP with ID
A11: 1029 | B11: Ahmed Elbarbary | C11: 1203424693 | D11: 45566 | E11: Monitoring Team Leader | F11: D | I11: Senior Dispatcher | K11: =COUNTIFS(F2:F458,"A",E2:E458,"Senior Dispatcher") -> 1 | M11: Senior Dispatcher | O11: =COUNTIFS(F2:F458,"B",E2:E458,"Senior Dispatcher") -> 0 | T11: =VLOOKUP(1053,A2:F642,2, FALSE) -> Mahmoud Mohamed Salama Kamalo
A12: 1051 | B12: Mahmoud Omar Mahmoud Hassan | C12: 1226199919 | D12: 45642 | E12: Monitoring Team Leader | F12: A | I12: Dispatcher | K12: =COUNTIFS(F2:F458,"A",E2:E458,"Dispatcher") -> 3 | M12: Dispatcher | O12: =COUNTIFS(F2:F458,"B",E2:E458,"Dispatcher") -> 3
A13: 1169 | B13: Karim Mahmoud Mahmoud Aleryan | C13: 1223837242 | D13: 45824 | E13: Monitoring Team Leader | F13: B | I13: Truck Foreman | K13: =COUNTIFS(F2:F458,"A",E2:E458,"Truck Foreman") -> 2 | M13: Truck Foreman | O13: =COUNTIFS(F2:F458,"B",E2:E458,"Truck Foreman") -> 2
A14: Dispatcher | I14: Lashing Foreman | K14: =COUNTIFS(F2:F458,"A",E2:E458,"Lashing Foreman") -> 2 | M14: Lashing Foreman | O14: =COUNTIFS(F2:F458,"B",E2:E458,"Lashing Foreman") -> 2
A15: ID | B15: Name | C15: Phone Number | D15: Hire Date | E15: Position | F15: Shift | I15: Roster Controller | K15: =COUNTIFS(F2:F458,"A",E2:E458,"Roster Controller") -> 0 | M15: Roster Controller | O15: =COUNTIFS(F2:F458,"B",E2:E458,"Roster Controller") -> 1
A16: 1102 | B16: Ahmed Fawzy Hussin Abdo Kadah | C16: 1064071811 | D16: 45781 | E16: Senior Dispatcher | F16: C | I16: Deck and Wharf | K16: =COUNTIFS(F2:F458,"A",E2:E458,"Deck and Wharf") -> 22 | M16: Dech and Wharf | O16: =COUNTIFS(F2:F458,"B",E2:E458,"Deck and Wharf") -> 22
A17: 1193 | B17: Ahmed Gamal Mohamed Ali Soliman | C17: 1124581132 | D17: 45860 | E17: Senior Dispatcher | F17: A | I17: STS Operator(fresh) | K17: =COUNTIFS(F2:F458,"A",E2:E458,"STS Fresh") -> 9 | L17: =SUM(K17+K18) -> 13 | M17: STS Operator(fresh) | O17: =COUNTIFS(F2:F458,"B",E2:E458,"STS Fresh") -> 8 | P17: =SUM(O17+O18) -> 13
A18: 1258 | B18: Mohamed Hassan Ahmed Aly Elkshawy | C18: 1285461167 | D18: 45914 | E18: Senior Dispatcher | F18: D | I18: STS Operator(experience) | K18: =COUNTIFS(F2:F458,"A",E2:E458,"STS Experience") -> 4 | M18: STS Operator(experience) | O18: =COUNTIFS(F2:F458,"B",E2:E458,"STS Experience") -> 5
A19: 1121 | B19: Abdelrahman Ashraf Awad Rakha Zaghlol | C19: 1061573966 | D19: 45809 | E19: Dispatcher | F19: A | I19: RTG Operator(fresh) | K19: =COUNTIFS(F2:F458,"A",E2:E458,"RTG Fresh") -> 20 | L19: =SUM(K19+K20) -> 30 | M19: RTG Operator(fresh) | O19: =COUNTIFS(F2:F458,"B",E2:E458,"RTG Fresh") -> 20 | P19: =SUM(O19+O20) -> 30
A20: 1122 | B20: Mohmed Mahmoud Abdelhamid Aboelregal | C20: 1033735010 | D20: 45809 | E20: Dispatcher | F20: C | I20: RTG Operator(experience) | K20: =COUNTIFS(F2:F458,"A",E2:E458,"RTG Experience") -> 10 | M20: RTG Operator(experience) | O20: =COUNTIFS(F2:F458,"B",E2:E458,"RTG Experience") -> 10
A21: 1126 | B21: Ahmed Mohamed Yousef Aboyousf | C21: 1016959027 | D21: 45809 | E21: Dispatcher | F21: D | I21: RS&EH Operators | K21: =COUNTIFS(F2:F458,"A",E2:E458,"RS&EH Experience") -> 3 | M21: RS&EH Operators | O21: =COUNTIFS(F2:F458,"B",E2:E458,"RS&EH Experience") -> 3
A22: 1127 | B22: Mohamed Yousef Abass Zaghloul Mousa | C22: 1061573966 | D22: 45809 | E22: Dispatcher | F22: D | I22: landside Clerk | K22: =COUNTIFS(F3:F459,"A",E3:E459,"landside Clerk") -> 8 | M22: landside Clerk | O22: =COUNTIFS(F3:F459,"B",E3:E459,"landside Clerk") -> 7
A23: 1146 | B23: Mohamed Gamal Nasr Elmetwaly | C23: 1095801434 | D23: 45809 | E23: Dispatcher | F23: D | I23: Planning Superintendent | K23: =COUNTIFS(F6:F462,"A",E6:E462,"Planning Superintendent") -> 1 | M23: Planning Superintendent | O23: =COUNTIFS(F4:F460,"B",E4:E460,"Planning Superintendent") -> 1
A24: 1153 | B24: Nader ALsayed Mohamed Ibrahim Eldesoky | C24: 1020036033 | D24: 45819 | E24: Dispatcher | F24: B | I24: Planner | K24: =COUNTIFS(F7:F463,"A",E7:E463,"Planner") -> 5 | M24: Planner | O24: =COUNTIFS(F5:F461,"B",E5:E461,"Planner") -> 4
A25: 1174 | B25: Mohamed Monir Taha Ghanam | C25: 1286889730 | D25: 45839 | E25: Dispatcher | F25: D
A26: 1175 | B26: Mohamed Metwaly Ibrahem Metwaly | C26: 1033990882 | D26: 45839 | E26: Dispatcher | F26: A
A27: 1192 | B27: Aseim Maher Fawzy Mohamed Seydan | C27: 1023101219 | D27: 45860 | E27: Dispatcher | F27: B
A28: 1199 | B28: Abdelrhman Ahmed Taha Hassan | C28: 1201401252 | D28: 45872 | E28: Dispatcher | F28: C | I28: C Shift | M28: D Shift
A29: 1425 | B29: Yahya Emadeldien Abbas Abdelsalam Qasem | C29: 1019614447 | D29: 45970 | E29: Dispatcher | F29: C | I29: OPS count | K29: =SUM(K30:K46) -> 95 | M29: OPS count | O29: =SUM(O30:O46) -> 92
A30: 1530 | B30: Ahmed Ameen Othman Ahmed Helbya | C30: 1557661323 | D30: 26/03/2026 | E30: Dispatcher | F30: A | I30: Shift Manager | K30: =COUNTIFS(F2:F458,"C",E2:E458,"Shift Manager") -> 1 | M30: Shift Manager | O30: =COUNTIFS(F2:F458,"D",E2:E458,"Shift Manager") -> 1
A31: 1531 | B31: Mohamed Yahya Othman Ibrahim Saleh | C31: 1206000428 | D31: 26/03/2026 | E31: Dispatcher | F31: B | I31: Operation Supervisor | K31: =COUNTIFS(F2:F458,"C",E2:E458,"Operation Supervisor") -> 3 | M31: Operation Supervisor | O31: =COUNTIFS(F2:F458,"D",E2:E458,"Operation Supervisor") -> 2
A32: Operation Supervisor | I32: Monitoring Team Leader | K32: =COUNTIFS(F2:F458,"C",E2:E458,"Monitoring Team Leader") -> 0 | M32: Monitoring Team Leader | O32: =COUNTIFS(F2:F458,"D",E2:E458,"Monitoring Team Leader") -> 1
A33: ID | B33: Name | C33: Phone Number | D33: Hire Date | E33: Position | F33: Shift | I33: Senior Dispatcher | K33: =COUNTIFS(F2:F458,"C",E2:E458,"Senior Dispatcher") -> 1 | M33: Senior Dispatcher | O33: =COUNTIFS(F2:F458,"D",E2:E458,"Senior Dispatcher") -> 1
A34: 1064 | B34: Mohamed Alsayed Abass Mohamed Abdelhady | C34: 1098111708 | D34: 45717 | E34: Operation Supervisor | F34: A | I34: Dispatcher | K34: =COUNTIFS(F2:F458,"C",E2:E458,"Dispatcher") -> 3 | M34: Dispatcher | O34: =COUNTIFS(F2:F458,"D",E2:E458,"Dispatcher") -> 4
A35: 1065 | B35: Mohamed Elsayed Abdo Elkamash | C35: 1017419875 | D35: 45717 | E35: Operation Supervisor | F35: B | I35: Truck Foreman | K35: =COUNTIFS(F2:F458,"C",E2:E458,"Truck Foreman") -> 2 | M35: Truck Foreman | O35: =COUNTIFS(F2:F458,"D",E2:E458,"Truck Foreman") -> 2
A36: 1067 | B36: Mohamed Saad Ahmed Mohamed Badr | C36: 1000044950 | D36: 45717 | E36: Operation Supervisor | F36: C | I36: Lashing Foreman | K36: =COUNTIFS(F2:F458,"C",E2:E458,"Lashing Foreman") -> 2 | M36: Lashing Foreman | O36: =COUNTIFS(F2:F458,"D",E2:E458,"Lashing Foreman") -> 2
A37: 1189 | B37: Mohamed Abo Bakr Khalifa Badawy | C37: 1006788757 | D37: 45854 | E37: Operation Supervisor | F37: D | I37: Roster Controller | K37: =COUNTIFS(F2:F458,"C",E2:E458,"Roster Controller") -> 1 | M37: Roster Controller | O37: =COUNTIFS(F2:F458,"D",E2:E458,"Roster Controller") -> 1
A38: 1372 | B38: Amr Ahmed Shabaan Abdelhamid Gomaa | C38: 1285478805 | D38: 45963 | E38: Operation Supervisor | F38: A | I38: Dech and Wharf | K38: =COUNTIFS(F2:F458,"C",E2:E458,"Deck and Wharf") -> 22 | M38: Dech and Wharf | O38: =COUNTIFS(F2:F458,"D",E2:E458,"Deck and Wharf") -> 21
A39: 1373 | B39: Tawheed Aly Younis Aly Younis | C39: 1223656736 | D39: 45963 | E39: Operation Supervisor | F39: D | I39: STS Operator(fresh) | K39: =COUNTIFS(F2:F458,"C",E2:E458,"STS Fresh") -> 8 | L39: =SUM(K39+K40) -> 12 | M39: STS Operator(fresh) | O39: =COUNTIFS(F2:F458,"D",E2:E458,"STS Fresh") -> 7 | P39: =SUM(O39+O40) -> 12
A40: 1374 | B40: Mahmoud Sherif Aly Moustafa Abdelmawgod | C40: 1064252990 | D40: 45963 | E40: Operation Supervisor | F40: C | I40: STS Operator(experience) | K40: =COUNTIFS(F2:F458,"C",E2:E458,"STS Experience") -> 4 | M40: STS Operator(experience) | O40: =COUNTIFS(F2:F458,"D",E2:E458,"STS Experience") -> 5
...

Sheet Sheet1

Sheet Employe Database
A1: ID | B1: Name | C1: Phone Number | D1: Hire Date | E1: Position
A2: 1019 | B2: Mohamed Ibrahim Mohamed Abo Omar | C2: 1013333299 | D2: 45452 | E2: Execution Manager
A3: 1022 | B3: Nader Helmy Abd elal Abbas | C3: 1099914441 | D3: 45505 | E3: Shift Manager
A4: 1023 | B4: Amr Soliman Mahmoud Soliman Rashwan | C4: 1226950094 | D4: 45515 | E4: Shift Manager
A5: 1052 | B5: Hatem Hosny Nafea Ali Moslem | C5: 1066681479 | D5: 45642 | E5: Shift Manager
A6: 1046 | B6: Mohamed Khalil AbdElhamied Khater | C6: 1014446422 | D6: 45597 | E6: Training Manager
A7: 1066 | B7: Salah Elsayed Elbadawy Mohamed Aleraky | C7: 1221618941 | D7: 45717 | E7: Lashing Supervisor
A8: 1028 | B8: Shady Gamal Abdel Nasser Mohamed AlQashash | C8: 1033010314 | D8: 45566 | E8: Shift Manager
A9: 1029 | B9: Ahmed Elbarbary | C9: 1203424693 | D9: 45566 | E9: Monitoring Team Leader
A10: 1051 | B10: Mahmoud Omar Mahmoud Hassan | C10: 1226199919 | D10: 45642 | E10: Monitoring Team Leader
A11: 1064 | B11: Mohamed Alsayed Abass Mohamed Abdelhady | C11: 1098111708 | D11: 45717 | E11: Operation Supervisor
A12: 1065 | B12: Mohamed Elsayed Abdo Elkamash | C12: 1017419875 | D12: 45717 | E12: Operation Supervisor
A13: 1067 | B13: Mohamed Saad Ahmed Mohamed Badr | C13: 1000044950 | D13: 45717 | E13: Operation Supervisor
... A107: 1227 | B107: Adel Ahmed Abdelghany Ahmed Eltayeb | C107: 1273594086 | D107: 45893 | E107: RTG Experience
A108: 1229 | B108: Islam Mohamed Elsaid Hussein Elsery | C108: 01202662252 | D108: 45893 | E108: RTG Experience
A109: 1231 | B109: Mohamed Khalf Hussin Khalifa | C109: 1276479738 | D109: 45893 | E109: RTG Experience
A110: 1225 | B110: Islam Ali Mossad Mahmoud Darwesh | C110: 1211889902 | D110: 45893 | E110: RTG Experience
A111: 1228 | B111: Mohamed Ashraf Abdelhakim Soliman Ibrahim Elghetany | C111: 1201067679 | D111: 45893 | E111: RTG Experience
A112: 1226 | B112: Ahmed Taysir Eldawody El-dawody | C112: 1225309592 | D112: 45893 | E112: RTG Experience
A113: 1232 | B113: Mahmoud Elsayed Mohamed Ahmed Masoud | C113: 1280406597 | D113: 45897 | E113: RTG Experience
A114: 1233 | B114: Ahmed Ibrahim Mohamed Ibrahim Abdo | C114: 1277993107 | D114: 45897 | E114: RTG Experience
A115: 1238 | B115: Mohamed Rasmy Kareem Hassan Elmansy | C115: 1023584129 | D115: 45901 | E115: RTG Fresh
A116: 1243 | B116: Ahmed Mahmoud Zaid Younes Zaid | C116: 1009427447 | D116: 45901 | E116: RTG Fresh
A117: 1251 | B117: Ayman Taher Younes Ibrahim Ghana | C117: 1012562977 | D117: 45901 | E117: RTG Fresh
A118: 1240 | B118: Ahmed Rabee Abdelftah Abdelall | C118: 1026664298 | D118: 45901 | E118: RTG Fresh
A119: 1235 | B119: Tarek Ramdan Mostafa Hmady | C119: 1090948201 | D119: 45901 | E119: RTG Fresh
A120: 1239 | B120: Ahmed Yehia Yehia Hussin | C120: 1014867758 | D120: 45901 | E120: RTG Fresh
A121: 1242 | B121: Abdalla Ahmed Ahmed Gomaa | C121: 1020731997 | D121: 45901 | E121: RTG Fresh
A122: 1244 | B122: Mohamed Ahmed Fawzy Eissa | C122: 1003122268 | D122: 45901 | E122: RTG Fresh
A123: 1236 | B123: Mohamed Elsayed Elsayed Abdelmksod | C123: 1013986591 | D123: 45901 | E123: RTG Fresh
A124: 1252 | B124: Mohamed Mohamed Taha El-Saeedi | C124: 1017074328 | D124: 45901 | E124: RTG Fresh
A125: 1246 | B125: Mohamed Medthat Abdelrhim Sakr | C125: 1020935606 | D125: 45901 | E125: RTG Fresh
A126: 1245 | B126: Ibrahim Elshahat Abdelaziz Metwaly | C126: 01022834268 | D126: 45901 | E126: RTG Fresh
A127: 1237 | B127: Osama Taha Mohamed Eldsoky Elsayed | C127: 1026981891 | D127: 45901 | E127: RTG Fresh
A128: 1257 | B128: Badr Tarek Saad Abogadalla | C128: 1066056501 | D128: 45909 | E128: RTG Fresh
A129: 1281 | B129: Mahmoud Mohamed Ramadan Mohamed Abdo El-Morsy | C129: 1124458004 | D129: 45923 | E129: RTG Experience
A130: 1283 | B130: Elsayed Aboelhassan Abdelazim Hashy | C130: 1285673745 | D130: 45923 | E130: RTG Experience
A131: 1280 | B131: Ahmed Alaa Mohamed Abdelal El-Eleidy | C131: 1555015440 | D131: 45923 | E131: RTG Experience
A132: 1272 | B132: Omar Ahmed Othman Abdelrahman Othman | C132: 1271190812 | D132: 45923 | E132: RTG Experience
A133: 1278 | B133: Belal Salah Salah Hamed Selim | C133: 1270939965 | D133: 45923 | E133: RTG Experience
...

Sheet Head Count 
A1: Execution Manager | B1: =COUNTIF('Employe Database'!E:E,"Execution Manager") -> 1 | D1: Shift Manager | E1: =COUNTIF('Employe Database'!E:E,"Shift Manager") -> 4 | H1: Training Manager | I1: =COUNTIF('Employe Database'!E:E,"Training Manager") -> 1 | K1: Lashing Supervisor | L1: =COUNTIF('Employe Database'!E:E,"Lashing Supervisor") -> 1 | O1: Monitoring Team Leader | P1: =COUNTIF('Employe Database'!E:E,"Monitoring Team Leader") -> 3 | R1: Total Headcount | V1: =SUM(B1,E1:E2,I1:I3,L1:L2,P1:P3,G6:G7,E8:E10) -> 324
D2: Operation Supervisor | E2: =COUNTIF('Employe Database'!E:E,"Operation Supervisor") -> 9 | H2: Training Supervisor | I2: =COUNTIF('Employe Database'!E:E,"Training Supervisor") -> 1 | K2: Lashing Foreman | L2: =COUNTIF('Employe Database'!E:E,"lashing Foreman") -> 9 | O2: Senior Dispatcher | P2: =COUNTIF('Employe Database'!E:E,"Senior Dispatcher") -> 3
H3: Truck Foreman | I3: =COUNTIF('Employe Database'!E:E,"Truck Foreman") -> 8 | O3: Dispatcher | P3: =COUNTIF('Employe Database'!E:E,"Dispatcher") -> 13
E5: EX | F5: FR | G5: Total
D6: STS Operators | E6: =COUNTIF('Employe Database'!E:E,"STS Experience") -> 18 | F6: =COUNTIF('Employe Database'!E:E,"STS Fresh") -> 30 | G6: =SUM(E6:F6) -> 48
D7: RTG Operators | E7: =COUNTIF('Employe Database'!E:E,"RTG Experience") -> 40 | F7: =COUNTIF('Employe Database'!E:E,"RTG Fresh") -> 80 | G7: =SUM(E7:F7) -> 120
D8: RS&EH Operators | E8: =COUNTIF('Employe Database'!E:E,"RS&EH Experience") -> 12
D9: D&W | E9: =COUNTIF('Employe Database'!E:E,"D&W") -> 87
D10: Roster Controller | E10: =COUNTIF('Employe Database'!E:E,"Roster Controller") -> 4
G12: A Shift | N12: C Shift
H13: Shift Manager | I13: =COUNTIF('HeadCount&Database '!F5:F8,"A") -> 0 | O13: Shift Manager | P13: =COUNTIF('HeadCount&Database '!F5:F8,"C") -> 1
H14: Operation Supervisor | I14: =COUNTIF('HeadCount&Database '!F34:F42,"A") -> 2 | O14: Operation Supervisor | P14: =COUNTIF('HeadCount&Database '!F34:F42,"C") -> 3
H15: Monitoring Team Leader | I15: =COUNTIF('HeadCount&Database '!F11:F13,"A") -> 1 | O15: Monitoring Team Leader | P15: =COUNTIF('HeadCount&Database '!F11:F13,"C") -> 0
H16: Senior Dispatcher | I16: =COUNTIF('HeadCount&Database '!F16:F18,"A") -> 1 | O16: Senior Dispatcher | P16: =COUNTIF('HeadCount&Database '!F16:F18,"C") -> 1
H17: Dispatcher | I17: =COUNTIF('HeadCount&Database '!F19:F31,"A") -> 3 | O17: Dispatcher | P17: =COUNTIF('HeadCount&Database '!F19:F31,"C") -> 3
H18: Truck Foreman | I18: =COUNTIF('HeadCount&Database '!F61:F68,"A") -> 2 | O18: Truck Foreman | P18: =COUNTIF('HeadCount&Database '!F61:F68,"C") -> 2
H19: Lashing Foreman | I19: =COUNTIF('HeadCount&Database '!F49:F58,"A") -> 2 | O19: Lashing Foreman | P19: =COUNTIF('HeadCount&Database '!F49:F58,"C") -> 2
H20: Roster Controller | I20: =COUNTIF('HeadCount&Database '!F71:F74,"A") -> 0 | O20: Roster Controller | P20: =COUNTIF('HeadCount&Database '!F71:F74,"C") -> 1
H21: D&W | I21: =COUNTIF('HeadCount&Database '!F264:F349,"A") -> 22 | O21: D&W | P21: =COUNTIF('HeadCount&Database '!F264:F349,"C") -> 22
H22: STS Operator | I22: =COUNTIF('HeadCount&Database '!F77:F124,"A") -> 12 | O22: STS Operator | P22: =COUNTIF('HeadCount&Database '!F77:F124,"C") -> 11
H23: RTG Operator | I23: =COUNTIF('HeadCount&Database '!F129:F246,"A") -> 30 | O23: RTG Operator | P23: =COUNTIF('HeadCount&Database '!F129:F251,"C") -> 31
H24: RS&EH Operators | I24: =COUNTIF('HeadCount&Database '!F250:F261,"A") -> 3 | O24: RS&EH Operators | P24: =COUNTIF('HeadCount&Database '!F250:F261,"C") -> 3
G26: B Shift | N26: D Shift
H27: Shift Manager | I27: =COUNTIF('HeadCount&Database '!F5:F8,"B") -> 1 | O27: Shift Manager | P27: =COUNTIF('HeadCount&Database '!F5:F8,"D") -> 1
H28: Operation Supervisor | I28: =COUNTIF('HeadCount&Database '!F34:F42,"B") -> 2 | O28: Operation Supervisor | P28: =COUNTIF('HeadCount&Database '!F34:F42,"D") -> 2
H29: Monitoring Team Leader | I29: =COUNTIF('HeadCount&Database '!F11:F13,"B") -> 1 | O29: Monitoring Team Leader | P29: =COUNTIF('HeadCount&Database '!F25:F27,"D") -> 1
H30: Senior Dispatcher | I30: =COUNTIF('HeadCount&Database '!F16:F18,"A") -> 1 | O30: Senior Dispatcher | P30: =COUNTIF('HeadCount&Database '!F16:F18,"D") -> 1
H31: Dispatcher | I31: =COUNTIF('HeadCount&Database '!F19:F31,"B") -> 3 | O31: Dispatcher | P31: =COUNTIF('HeadCount&Database '!F19:F31,"D") -> 4
H32: Truck Foreman | I32: =COUNTIF('HeadCount&Database '!F61:F68,"B") -> 2 | O32: Truck Foreman | P32: =COUNTIF('HeadCount&Database '!F61:F68,"D") -> 2
H33: Lashing Foreman | I33: =COUNTIF('HeadCount&Database '!F49:F58,"B") -> 2 | O33: Lashing Foreman | P33: =COUNTIF('HeadCount&Database '!F49:F58,"D") -> 2
H34: Roster Controller | I34: =COUNTIF('HeadCount&Database '!F71:F74,"B") -> 1 | O34: Roster Controller | P34: =COUNTIF('HeadCount&Database '!F71:F74,"D") -> 1
H35: D&W | I35: =COUNTIF('HeadCount&Database '!F264:F349,"B") -> 21 | O35: D&W | P35: =COUNTIF('HeadCount&Database '!F264:F349,"D") -> 21
H36: STS Operator | I36: =COUNTIF('HeadCount&Database '!F77:F124,"B") -> 13 | O36: STS Operator | P36: =COUNTIF('HeadCount&Database '!F77:F124,"D") -> 12
H37: RTG Operator | I37: =COUNTIF('HeadCount&Database '!F129:F246,"B") -> 30 | O37: RTG Operator | P37: =COUNTIF('HeadCount&Database '!F129:F246,"D") -> 29
H38: RS&EH Operators | I38: =COUNTIF('HeadCount&Database '!F250:F261,"B") -> 3 | O38: RS&EH Operators | P38: =COUNTIF('HeadCount&Database '!F250:F261,"D") -> 3
